<?xml version="1.0" ?>
<!-- =================================================================================== -->
<!-- |    This document was autogenerated by xacro from /home/pklimuk/ANRO/zadania/src/klimuk_stankevich/install/custom_urdf/share/custom_urdf/custom.urdf.xacro | -->
<!-- |    EDITING THIS FILE BY HAND IS NOT RECOMMENDED                                 | -->
<!-- =================================================================================== -->
<robot name="planar_3dof">
  <material name="red">
    <color rgba="0.8 0.0 0.0 1.0"/>
  </material>
  <material name="grey">
    <color rgba="0.4 0.4 0.4 1.0"/>
  </material>
  <link name="world">
    <visual>
      <origin rpy="0 0 0" xyz="0 0 0.15"/>
      <geometry>
        <box size="0.3 0.3 0.3"/>
      </geometry>
      <material name="grey">
      </material>
    </visual>
    <collision>
      <origin rpy="0 0 0" xyz="0 0 0.15"/>
      <geometry>
        <box size="0.3 0.3 0.3"/>
      </geometry>
      <material name="grey"/>
    </collision>
  </link>
  <link name="body">
    <visual>
      <origin rpy="0.0 0.0 0.0" xyz="0.0 0.0 2.5"/>
      <geometry>
        <cylinder length="5.0" radius="0.075"/>
      </geometry>
      <material name="grey">
      </material>
    </visual>
    <collision>
      <origin rpy="0.0 0.0 0.0" xyz="0.0 0.0 2.5"/>
      <geometry>
        <cylinder length="5.0" radius="0.075"/>
      </geometry>
      <material name="grey"/>
    </collision>
  </link>
  <joint name="fixed" type="fixed">
    <parent link="world"/>
    <child link="body"/>
  </joint>
  <link name="arm">
    <visual>
      <origin rpy="0 1.5708 0" xyz="1.0 0.0 0.0"/>
      <geometry>
        <cylinder length="2.0" radius="0.05"/>
      </geometry>
      <material name="red"/>
    </visual>
    <collision>
      <origin rpy="0 1.5708 0" xyz="1.0 0.0 0.0"/>
      <geometry>
        <cylinder length="2.0" radius="0.05"/>
      </geometry>
      <material name="red"/>
    </collision>
    <inertial>
      <origin rpy="0 1.5708 0" xyz="1.0 0.0 0.0"/>
      <mass value="1"/>
      <inertia ixx="1.0" ixy="0.0" ixz="0.0" iyy="1.0" iyz="0.0" izz="1.0"/>
    </inertial>
  </link>
  <joint name="shoulder" type="revolute">
    <parent link="body"/>
    <child link="arm"/>
    <origin rpy="0.0 0.0 0.0" xyz="0.0 0.0 5.0"/>
    <axis xyz="0 0 1"/>
    <limit effort="0" lower="-1.57" upper="1.57" velocity="0.5"/>
  </joint>
  <link name="forearm">
    <visual>
      <origin rpy="0 1.5708 0" xyz="1.5 0.0 0.0"/>
      <geometry>
        <cylinder length="3.0" radius="0.05"/>
      </geometry>
      <material name="grey"/>
    </visual>
    <collision>
      <origin rpy="0 1.5708 0" xyz="1.5 0.0 0.0"/>
      <geometry>
        <cylinder length="3.0" radius="0.05"/>
      </geometry>
      <material name="grey"/>
    </collision>
    <inertial>
      <origin rpy="0 1.5708 0" xyz="1.5 0.0 0.0"/>
      <mass value="1"/>
      <inertia ixx="1.0" ixy="0.0" ixz="0.0" iyy="1.0" iyz="0.0" izz="1.0"/>
    </inertial>
  </link>
  <joint name="elbow" type="revolute">
    <parent link="arm"/>
    <child link="forearm"/>
    <origin rpy="0.0 0.0 0.0" xyz="2.0 0.0 0.0"/>
    <axis xyz="0 0 1"/>
    <limit effort="0" lower="-1.57" upper="1.57" velocity="0.5"/>
  </joint>
  <link name="hand">
    <visual>
      <origin rpy="0.0 1.578 0.0" xyz="-1.5 0.0 0.0"/>
      <geometry>
        <cylinder length="3.0" radius="0.05"/>
      </geometry>
      <material name="red"/>
    </visual>
    <collision>
      <origin rpy="0.0 1.578 0.0" xyz="-1.5 0.0 0.0"/>
      <geometry>
        <cylinder length="3.0" radius="0.05"/>
      </geometry>
      <material name="red"/>
    </collision>
    <inertial>
      <origin rpy="0.0 1.578 0.0" xyz="-1.5 0.0 0.0"/>
      <mass value="1"/>
      <inertia ixx="1.0" ixy="0.0" ixz="0.0" iyy="1.0" iyz="0.0" izz="1.0"/>
    </inertial>
  </link>
  <link name="connector"/>
  <joint name="wrist" type="fixed">
    <parent link="forearm"/>
    <child link="connector"/>
    <origin rpy="-3.14 0 0" xyz="3.0 0.0 0.0"/>
  </joint>
  <joint name="wrist_connector" type="prismatic">
    <parent link="connector"/>
    <child link="hand"/>
    <origin rpy="0.0 1.578 0.0" xyz="0.0 0.0 0.0"/>
    <limit effort="1000.0" lower="0.0" upper="3.0" velocity="0.5"/>
  </joint>
  <link name="end">
    <visual>
      <origin rpy="0 0 0" xyz="0 0 0"/>
      <geometry>
        <box size="0.15 0.15 0.15"/>
      </geometry>
      <material name="grey"/>
    </visual>
    <collision>
      <origin rpy="0 0 0" xyz="0 0 0"/>
      <geometry>
        <box size="0.15 0.15 0.15"/>
      </geometry>
      <material name="grey"/>
    </collision>
    <inertial>
      <origin rpy="0 0 0" xyz="0 0 0"/>
      <mass value="1"/>
      <inertia ixx="1.0" ixy="0.0" ixz="0.0" iyy="1.0" iyz="0.0" izz="1.0"/>
    </inertial>
  </link>
  <joint name="fixed_end" type="fixed">
    <parent link="hand"/>
    <child link="end"/>
    <origin rpy="0.0 0.0 0.0" xyz="-3.0 0.0 0.0"/>
  </joint>
</robot>
