<?xml version="1.0"?>

<robot name="custom_urdf" xmlns:xacro="http://ros.org/wiki/xacro">


  <material name="red">
    <color rgba="0.8 0.0 0.0 1.0"/>
  </material>
  <material name="grey">
    <color rgba="0.4 0.4 0.4 1.0" />
  </material>


  <link name="world">
      <visual>
      <origin rpy="0 0 0" xyz="0 0 0.15" />
      <geometry>
        <box size="0.3 0.3 0.3"/>
      </geometry>
      <material name="grey">
      </material>
    </visual>
  <collision>
    <origin rpy="0 0 0" xyz="0 0 0.15" />
    <geometry>
      <box size="0.3 0.3 0.3"/>
    </geometry>
    <material name="grey"/>
  </collision>
  </link>

  <link name="body">
    <visual>
      <origin rpy="0 0 0" xyz="0 0 0.65" />
      <geometry>
        <cylinder length="1.3" radius="0.075" />
      </geometry>
      <material name="grey">
      </material>
    </visual>
  <collision>
    <origin rpy="0 0 0" xyz="0 0 0.65" />
    <geometry>
      <cylinder length="1.3" radius="0.075" />
    </geometry>
    <material name="grey"/>
  </collision>
  </link>

  <joint name="fixed" type="fixed">
    <parent link="world" />
    <child link="body" />
  </joint>

  <link name="arm">
    <visual>
      <origin xyz="0.25 0 0" rpy="0 1.5708 0" />
      <geometry>
        <cylinder length="0.5" radius="0.05" />
      </geometry>
      <material name="red"/>
    </visual>
    <collision>
      <origin rpy="0 1.5708 0" xyz="0.25 0 0" />
      <geometry>
        <cylinder length="0.5" radius="0.05" />
      </geometry>
      <material name="red"/>
    </collision>
    <inertial>
      <origin xyz="0.25 0 0" rpy="0 1.5708 0" />
      <mass value="1" />
      <inertia ixx="1.0" ixy="0.0" ixz="0.0" iyy="1.0" iyz="0.0" izz="1.0" />
    </inertial>
  </link>

  <joint name="shoulder" type="revolute">
    <parent link="body" />
    <child link="arm" />
    <origin xyz="0 0 1.3" rpy="0 0 0" />
    <axis xyz="0 0 1" />
    <limit lower="-1.57" upper="1.57" effort="0" velocity="0.5" />
  </joint>

  <link name="forearm">
    <visual>
      <origin xyz="0.25 0 0" rpy="0 1.5708 0" />
      <geometry>
        <cylinder length="0.5" radius="0.05" />
      </geometry>
      <material name="grey"/>
    </visual>
    <collision>
      <origin xyz="0.25 0 0" rpy="0 1.5708 0" />
      <geometry>
        <cylinder length="0.5" radius="0.05" />
      </geometry>
      <material name="grey"/>
    </collision>
    <inertial>
      <origin xyz="0.25 0 0" rpy="0 1.5708 0" />
      <mass value="1" />
      <inertia ixx="1.0" ixy="0.0" ixz="0.0" iyy="1.0" iyz="0.0" izz="1.0" />
    </inertial>
  </link>

  <joint name="elbow" type="revolute">
    <parent link="arm" />
    <child link="forearm" />
    <origin xyz="0.5 0.0 0.0" rpy="0.0 0 0.0" />
    <axis xyz="0 0 1" />
    <limit lower="-1.57" upper="1.57" effort="0" velocity="0.5" />
  </joint>

  <link name="hand">
    <visual>
      <origin xyz="-0.25 0 0" rpy="0 1.5708 0" />
      <geometry>
        <cylinder length="0.5" radius="0.05" />
      </geometry>
      <material name="red"/>
    </visual>
    <collision>
      <origin xyz="0.25 0 0" rpy="0 1.5708 0" />
      <geometry>
        <cylinder length="0.5" radius="0.05" />
      </geometry>
      <material name="red"/>
    </collision>
    <inertial>
      <origin xyz="0 0 0.25" rpy="0 1.5708 0" />
      <mass value="1" />
      <inertia ixx="1.0" ixy="0.0" ixz="0.0" iyy="1.0" iyz="0.0" izz="1.0" />
    </inertial>
  </link>

<link name="connector"/>

  <joint name="wrist" type="fixed">
    <parent link="forearm" />
    <child link="connector" />
    <origin xyz="0.5 0 0" rpy="-3.14 0 0" />
  </joint>



  <joint name="wrist_connector" type="prismatic">
    <parent link="connector" />
    <child link="hand" />
    <origin xyz="0.0 0 0.0" rpy="0.0 1.578 0" />
    <limit effort="1000.0" lower="0.0" upper="0.5" velocity="0.5"/>
  </joint>


<link name="end">
    <visual>
      <origin xyz="0 0 0" rpy="0 0 0" />
      <geometry>
        <box size="0.15 0.15 0.15"/>
      </geometry>
      <material name="grey"/>
    </visual>
    <collision>
      <origin xyz="0 0 0" rpy="0 0 0" />
      <geometry>
        <box size="0.15 0.15 0.15"/>
      </geometry>
      <material name="grey"/>
    </collision>
    <inertial>
      <origin xyz="0 0 0" rpy="0 0 0" />
      <mass value="1" />
      <inertia ixx="1.0" ixy="0.0" ixz="0.0" iyy="1.0" iyz="0.0" izz="1.0" />
    </inertial>
  </link>

 <joint name="fixed_end" type="fixed">
    <parent link="hand" />
    <child link="end" />
    <origin xyz="-0.5 0 0" rpy="0 0 0" />
  </joint>

</robot>
