<robot name="r2d2">
	<link name="link0_passive">
		<visual>
			<material name="blue">
				<color rgba="0 0 .8 1"/>
			</material>
			<geometry>
				<origin xyz="0 0 0" rpy="0 0 0"/>
				<cylinder length="0.0" radius="0.0"/>
			</geometry>
		</visual>
	</link>
	<link name="link0_x_axis">
		<visual>
			<material name="red">
				<color rgba="1 0 0 1"/>
			</material>
			<geometry>
				<origin xyz="0 0 0" rpy="0 0 0"/>
				<cylinder length="0.0" radius="0.0"/>
			</geometry>
		</visual>
	</link>
	<joint name="q0_x" type="fixed">
		<origin xyz="0 0 0" rpy="0 1.571 0"/>
		<parent link="link0_passive"/>
		<child link="link0_x_axis"/>
	</joint>
	<link name="link1"/>
	<link name="link1_x_axis">
		<visual>
			<origin xyz="0 0 0.25" rpy="0 0 0"/>
			<material name="red"/>
			<geometry>
				<cylinder length="0.5" radius="0.05"/>
			</geometry>
		</visual>
	</link>
	<joint name="q1" type="revolute">
		<origin xyz="0 0 0" rpy="0 0 0"/>
		<parent link="link0_passive"/>
		<child link="link1"/>
		<axis xyz="0 0 1"/>
	</joint>
	<joint name="q1_passive" type="fixed">
		<origin xyz="0 0 0" rpy="0 0 0"/>
		<parent link="link1"/>
		<child link="link1_passive"/>
	</joint>
	<link name="link1_passive">
		<visual>
			<origin xyz="0 0 0.25" rpy="0 0 0"/>
			<material name="blue"/>
			<geometry>
				<cylinder length="0.5" radius="0.05"/>
			</geometry>
		</visual>
	</link>
	<joint name="q1_x" type="fixed">
		<origin xyz="0 0 0" rpy="0 1.571 0"/>
		<parent link="link1_passive"/>
		<child link="link1_x_axis"/>
	</joint>
	<link name="link2"/>
	<link name="link2_x_axis">
		<visual>
			<origin xyz="0 0 0.25" rpy="0 0 0"/>
			<material name="red"/>
			<geometry>
				<cylinder length="0.5" radius="0.05"/>
			</geometry>
		</visual>
	</link>
	<joint name="q2" type="revolute">
		<origin xyz="0 0 0" rpy="0 0 0"/>
		<parent link="link1_passive"/>
		<child link="link2"/>
		<axis xyz="0 0 1"/>
	</joint>
	<joint name="q2_passive" type="fixed">
		<origin xyz="2 0 0" rpy="0 0 0"/>
		<parent link="link2"/>
		<child link="link2_passive"/>
	</joint>
	<link name="link2_passive">
		<visual>
			<origin xyz="0 0 0.25" rpy="0 0 0"/>
			<material name="blue"/>
			<geometry>
				<cylinder length="0.5" radius="0.05"/>
			</geometry>
		</visual>
	</link>
	<joint name="q2_x" type="fixed">
		<origin xyz="0 0 0" rpy="0 1.571 0"/>
		<parent link="link2_passive"/>
		<child link="link2_x_axis"/>
	</joint>
	<link name="link3"/>
	<link name="link3_x_axis">
		<visual>
			<origin xyz="0 0 0.25" rpy="0 0 0"/>
			<material name="red"/>
			<geometry>
				<cylinder length="0.5" radius="0.05"/>
			</geometry>
		</visual>
	</link>
	<joint name="q3" type="prismatic">
		<origin xyz="0 0 2" rpy="0 0 0"/>
		<parent link="link2_passive"/>
		<child link="link3"/>
		<axis xyz="0 0 1"/>
	</joint>
	<joint name="q3_passive" type="fixed">
		<origin xyz="2 0 0" rpy="3.141592653589793 0 0"/>
		<parent link="link3"/>
		<child link="link3_passive"/>
	</joint>
	<link name="link3_passive">
		<visual>
			<origin xyz="0 0 0.25" rpy="0 0 0"/>
			<material name="blue"/>
			<geometry>
				<cylinder length="0.5" radius="0.05"/>
			</geometry>
		</visual>
	</link>
	<joint name="q3_x" type="fixed">
		<origin xyz="0 0 0" rpy="0 1.571 0"/>
		<parent link="link3_passive"/>
		<child link="link3_x_axis"/>
	</joint>
</robot>
